Workbook

Sheet LIST
A1: NICTHS: 2019 and 2024
A2: List of Tables
A4: Items | B4: Respondent | C4: Table Number | D4: Table
A5: Profile | B5: Household | C5: 1 | D5: Estimated Number of Households
A6: Profile | B6: Individuals | C6: 2 | D6: Estimated Number of Individuals
A7: Profile | B7: Individuals | C7: 2a | D7: Estimated Number of Individuals by Sex and Region
A8: Cellphone | B8: Household | C8: 3 | D8: Households with Access to Communal or Shared Cellphone by any Household Member at Any Time
A9: Cellphone | B9: Household | C9: 4 | D9: Households with Cellphone That Can be Used by Any Household Member at Any Time by Type of Cellphone
A10: Cellphone | B10: Individuals | C10: 5 | D10: Individuals Who Used Cellphone
A11: Cellphone | B11: Individuals | C11: 6 | D11: Individuals Who Own Cellphone
A12: Cellphone | B12: Individuals | C12: 6 | D12: Cellphone Owners by Type of Cellphone
A13: Cellphone | B13: Individuals | C13: 7 | D13: Cellphone Owners by Type of SIM Used
A14: SIM Registration | B14: Individuals | C14: 8 | D14: Individuals with ICT Device and Active SIM by Details Used in SIM Registration
A15: SIM Registration | B15: Individuals | C15: 9 | D15: Individuals with ICT Device and Active SIM Who Did Not Use Own Information in SIM Registration by Main Reason
A16: SIM Registration | B16: Individuals | C16: 10 | D16: Individuals with ICT Device, Active SIM and Registered SIM by Main Difficulty Encountered
A17: SIM Registration | B17: Individuals | C17: 11 | D17: Individual Average Monthly Spending on Load or Subscription
A18: Computer | B18: Household | C18: 12 | D18: Households with Computer That Can be Used by Any Household Member at Any Time
A19: Computer | B19: Household | C19: 13 | D19: Households with Computer That Can be Used by Any Household Member at Any Time by Type
A20: Computer | B20: Household | C20: 14 | D20: Households Accessing a Computer By Alternative Access Method
A21: Computer | B21: Individuals | C21: 15 | D21: Individuals Using a Computer
A22: Computer | B22: Individuals | C22: 15 | D22: Computer Users by Type
A23: Computer | B23: Individuals | C23: 16 | D23: Individuals Using Computer by Activity
A24: Internet | B24: Household | C24: 17 | D24: Households With/Have Access to the Internet
A25: Internet | B25: Household | C25: 18 | D25: Households with Internet by Usage of Internet
A26: Internet | B26: Household | C26: 19 | D26: Households Average Monthly Spending on Internet
A27: Internet | B27: Individuals | C27: 20 | D27: Individuals Using the Internet
A28: Internet | B28: Individuals | C28: 20 | D28: Individuals Using the Internet by Type of Device Used
A29: Internet | B29: Individuals | C29: 21 | D29: Individuals Using the Internet by Access Location
A30: Internet | B30: Individuals | C30: 22 | D30: Individuals Using the Internet by Frequency
A31: Internet | B31: Individuals | C31: 23 | D31: Top 5 Purposes for Using the Internet by Individuals
A32: Internet | B32: Household | C32: 24 | D32: Top 5 Barriers for Not Having Internet Connection at Home in 2024
A33: Internet | B33: Individuals | C33: 25 | D33: Top 5 Barriers to Internet Access in 2024 by Individuals
A34: Television | B34: Household | C34: 26 | D34: Households Access to Television
A35: Television | B35: Household | C35: 27 | D35: Households Access to Television by Type
A36: Digital Economy/E-Commerce | B36: Individuals | C36: 28 | D36: individuals Who Have Online Bank Account
A37: Digital Economy/E-Commerce | B37: Individuals | C37: 28 | D37: Individuals with an ICT Device and an Active SIM Who Have Electronic/Mobile Money Account
A38: Digital Economy/E-Commerce | B38: Individuals | C38: 29 | D38: Individuals Who Have Electronic/Mobile Money Account
A39: Digital Economy/E-Commerce | B39: Individuals | C39: 30 | D39: Individuals Who are Engaged in Online Activities to Earn Money by Type of Activity
A40: Digital Economy/E-Commerce | B40: Individuals | C40: 28 | D40: Individuals Who have an Online Buying or Online Selling Accounts
A41: Digital Economy/E-Commerce | B41: Individuals | C41: 30 | D41: Individuals Who are Internet Users and Selling Goods Online to Earn Money
...

Sheet Estimated Totals
A1: BACK TO LIST
A2: Table #. Estimated Number of Households and Individuals Aged 10 and Over by Region, Philippines: 2019 and 2024p
A4: Region | B4: Number of Households | D4: Number of Individuals
B5: 2019 | C5: 2024 | D5: 2019* | E5: 2024
A7: PHILIPPINES | B7: 23360960 | C7: 27793884 | D7: 83258836 | E7: 91383228
A8: National Capital Region | B8: 3009545 | C8: 3667731 | D8: 11005073 | E8: 11919468
A9: Cordillera Administrative Region | B9: 388188 | C9: 468413 | D9: 1394660 | E9: 1496049
A10: Region I - Ilocos Region | B10: 1250337 | C10: 1316881 | D10: 4063052 | E10: 4389510
A11: Region II - Cagayan Valley | B11: 855893 | C11: 934252 | D11: 2820240 | E11: 3055894
A12: Region III - Central Luzon | B12: 2823200 | C12: 3161851 | D12: 9585315 | E12: 10708290
A13: Region IV-A - CALABARZON | B13: 3486186 | C13: 4369198 | D13: 12457452 | E13: 13985526
A14: MIMAROPA Region | B14: 686916 | C14: 828498 | D14: 2347582 | E14: 2538126
A15: Region V - Bicol Region | B15: 1030986 | C15: 1384033 | D15: 4528646 | E15: 4884805
A16: Region VI - Western Visayas | B16: 1705556 | C16: 2040922 | D16: 6087553 | E16: 6586874
A17: Region VII - Central Visayas | B17: 1820052 | C17: 2077216 | D17: 6058752 | E17: 6668940
A18: Region VIII - Eastern Visayas | B18: 1042723 | C18: 1200913 | D18: 3529248 | E18: 3864215
... A24: Bangsamoro Autonomous Region in Muslim Mindanao | B24: 521349 | C24: 846042 | D24: 2943119 | E24: 3746618
A27: Notes:
A28: Details may not add up to totals due to rounding.
A29: * Based on the July 2019 Population Projection.
A30: p Estimates are preliminary and may change
A31: Source of data: Philippine Statistics Authority, 2024 National Information and Communications Technology Household Survey.

Sheet Estimated Individuals by Sex
A1: BACK TO LIST
A2: Table #. Estimated Number of Individuals Aged 10 and Over by Region and Sex, Philippines: 2024p
A4: Region | B4: Number of Individuals
B5: Total | C5: Male | D5: Female
A7: PHILIPPINES | B7: 91383228 | C7: 45892072 | D7: 45491156
A8: National Capital Region | B8: 11919468 | C8: 5828575 | D8: 6090893
A9: Cordillera Administrative Region | B9: 1496049 | C9: 758033 | D9: 738016
A10: Region I - Ilocos Region | B10: 4389510 | C10: 2203738 | D10: 2185772
A11: Region II - Cagayan Valley | B11: 3055894 | C11: 1547225 | D11: 1508669
A12: Region III - Central Luzon | B12: 10708290 | C12: 5386609 | D12: 5321681
A13: Region IV-A - CALABARZON | B13: 13985526 | C13: 6942876 | D13: 7042650
A14: MIMAROPA Region | B14: 2538126 | C14: 1296138 | D14: 1241988
A15: Region V - Bicol Region | B15: 4884805 | C15: 2481154 | D15: 2403651
A16: Region VI - Western Visayas | B16: 6586874 | C16: 3329796 | D16: 3257078
A17: Region VII - Central Visayas | B17: 6668940 | C17: 3364353 | D17: 3304587
A18: Region VIII - Eastern Visayas | B18: 3864215 | C18: 1981621 | D18: 1882594
... A24: Bangsamoro Autonomous Region in Muslim Mindanao | B24: 3746618 | C24: 1849043 | D24: 1897575
A27: Notes:
A28: Details may not add up to totals due to rounding.
A29: p Estimates are preliminary and may change
A30: Source of data: Philippine Statistics Authority, 2024 National Information and Communications Technology Household Survey.

Sheet c27
A1: BACK TO LIST
A2: Table #. Number and Percentage of Households with Access to Communal or Shared Cellphone by any Household Member at Any Time by Region, Philippines: 2019 and 2024p
A4: Region | B4: 2019 | E4: 2024
B5: Total Households | C5: With Access to Communal or Shared Cellphone | E5: Total Households | F5: With Access to Communal or Shared Cellphone
C6: Number | D6: Proportion | F6: Number | G6: Proportion
A8: PHILIPPINES | B8: ='Estimated Totals'!B7 -> 23360960 | C8: 5616891 | D8: =(C8/B8)*100 -> 24.043922 | E8: 27793884 | F8: 3633210 | G8: =(F8/E8)*100 -> 13.071977
A9: National Capital Region | B9: ='Estimated Totals'!B8 -> 3009545 | C9: 361042 | D9: =(C9/B9)*100 -> 11.996564 | E9: 3667731 | F9: 514743 | G9: =(F9/E9)*100 -> 14.034372
A10: Cordillera Administrative Region | B10: ='Estimated Totals'!B9 -> 388188 | C10: 96263 | D10: =(C10/B10)*100 -> 24.798036 | E10: 468413 | F10: 13931 | G10: =(F10/E10)*100 -> 2.9740848
A11: Region I - Ilocos Region | B11: ='Estimated Totals'!B10 -> 1250337 | C11: 154243 | D11: =(C11/B11)*100 -> 12.336114 | E11: 1316881 | F11: 110041 | G11: =(F11/E11)*100 -> 8.356184
A12: Region II - Cagayan Valley | B12: ='Estimated Totals'!B11 -> 855893 | C12: 328525 | D12: =(C12/B12)*100 -> 38.383887 | E12: 934252 | F12: 177943 | G12: =(F12/E12)*100 -> 19.046574
A13: Region III - Central Luzon | B13: ='Estimated Totals'!B12 -> 2823200 | C13: 737821 | D13: =(C13/B13)*100 -> 26.134209 | E13: 3161851 | F13: 537446 | G13: =(F13/E13)*100 -> 16.997828
A14: Region IV-A - CALABARZON | B14: ='Estimated Totals'!B13 -> 3486186 | C14: 368496 | D14: =(C14/B14)*100 -> 10.570176 | E14: 4369198 | F14: 554046 | G14: =(F14/E14)*100 -> 12.680725
A15: MIMAROPA Region | B15: ='Estimated Totals'!B14 -> 686916 | C15: 127459 | D15: =(C15/B15)*100 -> 18.555253 | E15: 828498 | F15: 41005 | G15: =(F15/E15)*100 -> 4.9493179
A16: Region V - Bicol Region | B16: ='Estimated Totals'!B15 -> 1030986 | C16: 269349 | D16: =(C16/B16)*100 -> 26.125379 | E16: 1384033 | F16: 314774 | G16: =(F16/E16)*100 -> 22.743244
A17: Region VI - Western Visayas | B17: ='Estimated Totals'!B16 -> 1705556 | C17: 580410 | D17: =(C17/B17)*100 -> 34.030545 | E17: 2040922 | F17: 174752 | G17: =(F17/E17)*100 -> 8.5624046
A18: Region VII - Central Visayas | B18: ='Estimated Totals'!B17 -> 1820052 | C18: 341703 | D18: =(C18/B18)*100 -> 18.774354 | E18: 2077216 | F18: 109608 | G18: =(F18/E18)*100 -> 5.276678
A19: Region VIII - Eastern Visayas | B19: ='Estimated Totals'!B18 -> 1042723 | C19: 80941 | D19: =(C19/B19)*100 -> 7.7624642 | E19: 1200913 | F19: 83721 | G19: =(F19/E19)*100 -> 6.9714459
... A25: Bangsamoro Autonomous Region in Muslim Mindanao | B25: ='Estimated Totals'!B24 -> 521349 | C25: 249945 | D25: =(C25/B25)*100 -> 47.941974 | E25: 846042 | F25: 190555 | G25: =(F25/E25)*100 -> 22.523114
A28: Notes:
A29: Details may not add up to totals due to rounding.
A30: p Estimates are preliminary and may change
A31: Source of data: Philippine Statistics Authority, 2024 National Information and Communications Technology Household Survey.

Sheet c28_a and b
A1: BACK TO LIST
A2: Table #. Number and Proportion of Households with Access to Communal or Shared Cellphone by Type of Cellphone by Region, Philippines: 2024p
A4: Region | B4: 2024
B5: With Access to Communal or Shared Cellphone | C5: Basic Cellphone | E5: Smart Phone
C6: Number | D6: Proportion | E6: Number | F6: Proportion
A8: PHILIPPINES | B8: 3633210 | C8: 542871 | D8: =(C8/B8)*100 -> 14.941911 | E8: 3305348 | F8: =(E8/B8)*100 -> 90.975969
A9: National Capital Region | B9: 514743 | C9: 44992 | D9: =(C9/B9)*100 -> 8.7406725 | E9: 491247 | F9: =(E9/B9)*100 -> 95.435392
A10: Cordillera Administrative Region | B10: 13931 | C10: 3545 | D10: =(C10/B10)*100 -> 25.446845 | E10: 11223 | F10: =(E10/B10)*100 -> 80.561338
A11: Region I - Ilocos Region | B11: 110041 | C11: 10380 | D11: =(C11/B11)*100 -> 9.4328478 | E11: 106070 | F11: =(E11/B11)*100 -> 96.391345
A12: Region II - Cagayan Valley | B12: 177943 | C12: 35501 | D12: =(C12/B12)*100 -> 19.950771 | E12: 163111 | F12: =(E12/B12)*100 -> 91.664747
A13: Region III - Central Luzon | B13: 537446 | C13: 57482 | D13: =(C13/B13)*100 -> 10.6954 | E13: 516563 | F13: =(E13/B13)*100 -> 96.1144
A14: Region IV-A - CALABARZON | B14: 554046 | C14: 44999 | D14: =(C14/B14)*100 -> 8.1218888 | E14: 521611 | F14: =(E14/B14)*100 -> 94.145793
A15: MIMAROPA Region | B15: 41005 | C15: 4920 | D15: =(C15/B15)*100 -> 11.998537 | E15: 36666 | F15: =(E15/B15)*100 -> 89.418364
A16: Region V - Bicol Region | B16: 314774 | C16: 25667 | D16: =(C16/B16)*100 -> 8.1541042 | E16: 301454 | F16: =(E16/B16)*100 -> 95.768393
A17: Region VI - Western Visayas | B17: 174752 | C17: 19136 | D17: =(C17/B17)*100 -> 10.950375 | E17: 163520 | F17: =(E17/B17)*100 -> 93.572606
A18: Region VII - Central Visayas | B18: 109608 | C18: 23989 | D18: =(C18/B18)*100 -> 21.886176 | E18: 88082 | F18: =(E18/B18)*100 -> 80.360923
A19: Region VIII - Eastern Visayas | B19: 83721 | C19: 9284 | D19: =(C19/B19)*100 -> 11.089213 | E19: 75303 | F19: =(E19/B19)*100 -> 89.945175
... A25: Bangsamoro Autonomous Region in Muslim Mindanao | B25: 190555 | C25: 108843 | D25: =(C25/B25)*100 -> 57.118942 | E25: 128143 | F25: =(E25/B25)*100 -> 67.247251
A28: Notes:
A29: Details may not add up to totals due to rounding.
A30: p Estimates are preliminary and may change
A31: Source of data: Philippine Statistics Authority, 2024 National Information and Communications Technology Household Survey.

Sheet i_C6
A1: BACK TO LIST
A2: Table #. Number and Proportion of Individuals Who Used a Cellphone by Region, Philippines: 2019r and 2024p
A4: Region | B4: 2019 | E4: 2024
B5: Total Individuals | C5: Used a Cellphone | E5: Total Individuals | F5: Used a Cellphone
C6: Number | D6: Proportion | F6: Number | G6: Proportion
A8: PHILIPPINES | B8: ='Estimated Totals'!D7 -> 83258836 | C8: 35596631 | D8: =(C8/$B8)*100 -> 42.754178 | E8: 91383228 | F8: 74604857 | G8: =(F8/$E8)*100 -> 81.639551
A9: National Capital Region | B9: ='Estimated Totals'!D8 -> 11005073 | C9: 5768766 | D9: =(C9/$B9)*100 -> 52.419153 | E9: 11919468 | F9: 11067327 | G9: =(F9/$E9)*100 -> 92.850847
A10: Cordillera Administrative Region | B10: ='Estimated Totals'!D9 -> 1394660 | C10: 558479 | D10: =(C10/$B10)*100 -> 40.044097 | E10: 1496049 | F10: 1275461 | G10: =(F10/$E10)*100 -> 85.255296
A11: Region I - Ilocos Region | B11: ='Estimated Totals'!D10 -> 4063052 | C11: 2042932 | D11: =(C11/$B11)*100 -> 50.280725 | E11: 4389510 | F11: 3697111 | G11: =(F11/$E11)*100 -> 84.226053
A12: Region II - Cagayan Valley | B12: ='Estimated Totals'!D11 -> 2820240 | C12: 1435281 | D12: =(C12/$B12)*100 -> 50.892158 | E12: 3055894 | F12: 2601214 | G12: =(F12/$E12)*100 -> 85.121212
A13: Region III - Central Luzon | B13: ='Estimated Totals'!D12 -> 9585315 | C13: 4868143 | D13: =(C13/$B13)*100 -> 50.787512 | E13: 10708290 | F13: 9150022 | G13: =(F13/$E13)*100 -> 85.448022
A14: Region IV-A - CALABARZON | B14: ='Estimated Totals'!D13 -> 12457452 | C14: 6007369 | D14: =(C14/$B14)*100 -> 48.223096 | E14: 13985526 | F14: 12243411 | G14: =(F14/$E14)*100 -> 87.543443
A15: MIMAROPA Region | B15: ='Estimated Totals'!D14 -> 2347582 | C15: 906922 | D15: =(C15/$B15)*100 -> 38.632176 | E15: 2538126 | F15: 1994623 | G15: =(F15/$E15)*100 -> 78.586445
A16: Region V - Bicol Region | B16: ='Estimated Totals'!D15 -> 4528646 | C16: 1707802 | D16: =(C16/$B16)*100 -> 37.711095 | E16: 4884805 | F16: 3669067 | G16: =(F16/$E16)*100 -> 75.111842
A17: Region VI - Western Visayas | B17: ='Estimated Totals'!D16 -> 6087553 | C17: 2127227 | D17: =(C17/$B17)*100 -> 34.943876 | E17: 6586874 | F17: 5061672 | G17: =(F17/$E17)*100 -> 76.844828
A18: Region VII - Central Visayas | B18: ='Estimated Totals'!D17 -> 6058752 | C18: 1540479 | D18: =(C18/$B18)*100 -> 25.425682 | E18: 6668940 | F18: 5435569 | G18: =(F18/$E18)*100 -> 81.505742
A19: Region VIII - Eastern Visayas | B19: ='Estimated Totals'!D18 -> 3529248 | C19: 1650577 | D19: =(C19/$B19)*100 -> 46.768518 | E19: 3864215 | F19: 2961963 | G19: =(F19/$E19)*100 -> 76.651092
... A25: Bangsamoro Autonomous Region in Muslim Mindanao | B25: ='Estimated Totals'!D24 -> 2943119 | C25: 764912 | D25: =(C25/$B25)*100 -> 25.989843 | E25: 3746618 | F25: 2456282 | G25: =(F25/$E25)*100 -> 65.55998
A28: Notes:
A29: Details may not add up to totals due to rounding.
A30: p Estimates are preliminary and may change
A31: r Revised
A32: Source of data: Philippine Statistics Authority, 2024 National Information and Communications Technology Household Survey.

Sheet i_C8
A1: BACK TO LIST
A2: Table #. Number and Proportion of Individuals Who Own a Cellphone by Type of Cellphone and Region, Philippines: 2019r and 2024p
A4: Region | B4: 2019 | I4: 2024
B5: Total Individuals | C5: Cellphone Owners | E5: Type of Cellphone | I5: Total Individuals | J5: Cellphone Owners | L5: Type of Cellphone
E6: Basic/Analog Phone | G6: Smartphone | L6: Basic/Analog Phone | N6: Smartphone
C7: Number | D7: Proportion | E7: Number | F7: Proportion | G7: Number | H7: Proportion | J7: Number | K7: Proportion | L7: Number | M7: Proportion | N7: Number | O7: Proportion
A9: PHILIPPINES | B9: ='Estimated Totals'!D7 -> 83258836 | C9: 33940106 | D9: =(C9/$B9)*100 -> 40.76457 | E9: 10656100 | F9: =(E9/$C9)*100 -> 31.396778 | G9: 24261441 | H9: =(G9/$C9)*100 -> 71.483104 | I9: 91383228 | J9: 72873415 | K9: =(J9/$I9)*100 -> 79.744847 | L9: 5516992 | M9: =(L9/$J9)*100 -> 7.5706511 | N9: 67746423 | O9: =(N9/$J9)*100 -> 92.964523
A10: National Capital Region | B10: ='Estimated Totals'!D8 -> 11005073 | C10: 5613470.5 | D10: =(C10/$B10)*100 -> 51.008026 | E10: 708861.96 | F10: =(E10/$C10)*100 -> 12.627873 | G10: 5042024.5 | H10: =(G10/$C10)*100 -> 89.820093 | I10: 11919468 | J10: 10924677 | K10: =(J10/$I10)*100 -> 91.654065 | L10: 156776 | M10: =(L10/$J10)*100 -> 1.435063 | N10: 10793232 | O10: =(N10/$J10)*100 -> 98.796807
A11: Cordillera Administrative Region | B11: ='Estimated Totals'!D9 -> 1394660 | C11: 556690.66 | D11: =(C11/$B11)*100 -> 39.915869 | E11: 222736.6 | F11: =(E11/$C11)*100 -> 40.010837 | G11: 344665.61 | H11: =(G11/$C11)*100 -> 61.913309 | I11: 1496049 | J11: 1277366 | K11: =(J11/$I11)*100 -> 85.382631 | L11: 158661 | M11: =(L11/$J11)*100 -> 12.420951 | N11: 1138648 | O11: =(N11/$J11)*100 -> 89.140309
A12: Region I - Ilocos Region | B12: ='Estimated Totals'!D10 -> 4063052 | C12: 2001306 | D12: =(C12/$B12)*100 -> 49.256224 | E12: 677748.2 | F12: =(E12/$C12)*100 -> 33.865296 | G12: 1418816.9 | H12: =(G12/$C12)*100 -> 70.894552 | I12: 4389510 | J12: 3683268 | K12: =(J12/$I12)*100 -> 83.910687 | L12: 200746 | M12: =(L12/$J12)*100 -> 5.4502143 | N12: 3482522 | O12: =(N12/$J12)*100 -> 94.549786
A13: Region II - Cagayan Valley | B13: ='Estimated Totals'!D11 -> 2820240 | C13: 1344522.4 | D13: =(C13/$B13)*100 -> 47.674043 | E13: 574121.17 | F13: =(E13/$C13)*100 -> 42.70075 | G13: 832935.16 | H13: =(G13/$C13)*100 -> 61.950261 | I13: 3055894 | J13: 2451050 | K13: =(J13/$I13)*100 -> 80.207298 | L13: 201403 | M13: =(L13/$J13)*100 -> 8.217009 | N13: 2260260 | O13: =(N13/$J13)*100 -> 92.215989
A14: Region III - Central Luzon | B14: ='Estimated Totals'!D12 -> 9585315 | C14: 4847012.4 | D14: =(C14/$B14)*100 -> 50.567065 | E14: 1388040.8 | F14: =(E14/$C14)*100 -> 28.637038 | G14: 3593231.3 | H14: =(G14/$C14)*100 -> 74.13291 | I14: 10708290 | J14: 9021916 | K14: =(J14/$I14)*100 -> 84.251697 | L14: 432819 | M14: =(L14/$J14)*100 -> 4.7974178 | N14: 8610854 | O14: =(N14/$J14)*100 -> 95.443739
A15: Region IV-A - CALABARZON | B15: ='Estimated Totals'!D13 -> 12457452 | C15: 5566196.9 | D15: =(C15/$B15)*100 -> 44.681664 | E15: 1161361.4 | F15: =(E15/$C15)*100 -> 20.864541 | G15: 4538133.3 | H15: =(G15/$C15)*100 -> 81.530234 | I15: 13985526 | J15: 12081369 | K15: =(J15/$I15)*100 -> 86.384802 | L15: 565208 | M15: =(L15/$J15)*100 -> 4.678344 | N15: 11574712 | O15: =(N15/$J15)*100 -> 95.806295
A16: MIMAROPA Region | B16: ='Estimated Totals'!D14 -> 2347582 | C16: 761294.45 | D16: =(C16/$B16)*100 -> 32.428876 | E16: 291383.62 | F16: =(E16/$C16)*100 -> 38.27476 | G16: 506241.65 | H16: =(G16/$C16)*100 -> 66.497483 | I16: 2538126 | J16: 1900349 | K16: =(J16/$I16)*100 -> 74.87213 | L16: 152671 | M16: =(L16/$J16)*100 -> 8.0338401 | N16: 1757178 | O16: =(N16/$J16)*100 -> 92.466068
A17: Region V - Bicol Region | B17: ='Estimated Totals'!D15 -> 4528646 | C17: 1690938.7 | D17: =(C17/$B17)*100 -> 37.338726 | E17: 522906.83 | F17: =(E17/$C17)*100 -> 30.924055 | G17: 1194218.5 | H17: =(G17/$C17)*100 -> 70.624586 | I17: 4884805 | J17: 3577241 | K17: =(J17/$I17)*100 -> 73.232012 | L17: 204844 | M17: =(L17/$J17)*100 -> 5.7263125 | N17: 3404672 | O17: =(N17/$J17)*100 -> 95.175919
A18: Region VI - Western Visayas | B18: ='Estimated Totals'!D16 -> 6087553 | C18: 2159752 | D18: =(C18/$B18)*100 -> 35.478164 | E18: 722128.07 | F18: =(E18/$C18)*100 -> 33.435694 | G18: 1517000.4 | H18: =(G18/$C18)*100 -> 70.239565 | I18: 6586874 | J18: 4990093 | K18: =(J18/$I18)*100 -> 75.758137 | L18: 389379 | M18: =(L18/$J18)*100 -> 7.8030409 | N18: 4622547 | O18: =(N18/$J18)*100 -> 92.634486
A19: Region VII - Central Visayas | B19: ='Estimated Totals'!D17 -> 6058752 | C19: 1476407.2 | D19: =(C19/$B19)*100 -> 24.368173 | E19: 703079.31 | F19: =(E19/$C19)*100 -> 47.620963 | G19: 834318.78 | H19: =(G19/$C19)*100 -> 56.510073 | I19: 6668940 | J19: 5296648 | K19: =(J19/$I19)*100 -> 79.422637 | L19: 440263 | M19: =(L19/$J19)*100 -> 8.3121061 | N19: 4895590 | O19: =(N19/$J19)*100 -> 92.428079
A20: Region VIII - Eastern Visayas | B20: ='Estimated Totals'!D18 -> 3529248 | C20: 1318328.5 | D20: =(C20/$B20)*100 -> 37.354374 | E20: 432071.58 | F20: =(E20/$C20)*100 -> 32.774197 | G20: 917823.48 | H20: =(G20/$C20)*100 -> 69.62024 | I20: 3864215 | J20: 2705948 | K20: =(J20/$I20)*100 -> 70.025814 | L20: 193374 | M20: =(L20/$J20)*100 -> 7.1462571 | N20: 2524972 | O20: =(N20/$J20)*100 -> 93.311919
... A26: Bangsamoro Autonomous Region in Muslim Mindanao | B26: ='Estimated Totals'!D24 -> 2943119 | C26: 779688.76 | D26: =(C26/$B26)*100 -> 26.491921 | E26: 569733.04 | F26: =(E26/$C26)*100 -> 73.071855 | G26: 211031.81 | H26: =(G26/$C26)*100 -> 27.066161 | I26: 3746618 | J26: 2608489 | K26: =(J26/$I26)*100 -> 69.622497 | L26: 787402 | M26: =(L26/$J26)*100 -> 30.186135 | N26: 1848389 | O26: =(N26/$J26)*100 -> 70.860525
A29: Notes:
A30: Details may not add up to totals due to rounding.
A31: p Estimates are preliminary and may change
A32: r Revised
A33: Source of data: Philippine Statistics Authority, 2024 National Information and Communications Technology Household Survey.

Sheet i_C8&11
A1: BACK TO LIST
A2: Table #. Number and Proportion of Cellphone Owners by Type of SIM Card Used and Region, Philippines: 2019r and 2024p
A4: Region | B4: 2019 | G4: 2024
B5: Cellphone Owners | C5: Prepaid | E5: Postpaid | G5: Cellphone Owners | H5: Prepaid | J5: Postpaid
C6: Number | D6: Proportion | E6: Number | F6: Proportion | H6: Number | I6: Proportion | J6: Number | K6: Proportion
A8: PHILIPPINES | B8: =i_C8!C9 -> 33940106 | C8: 33189995 | D8: =(C8/$B8)*100 -> 97.789896 | E8: 818864.67 | F8: =(E8/$B8)*100 -> 2.4126756 | G8: 72873415 | H8: 70966582 | I8: =(H8/$G8)*100 -> 97.383363 | J8: 2257234 | K8: =(J8/$G8)*100 -> 3.0974725
A9: National Capital Region | B9: =i_C8!C10 -> 5613470.5 | C9: 5355014.8 | D9: =(C9/$B9)*100 -> 95.395794 | E9: 263894.89 | F9: =(E9/$B9)*100 -> 4.7011005 | G9: 10924677 | H9: 10594051 | I9: =(H9/$G9)*100 -> 96.973586 | J9: 436615 | K9: =(J9/$G9)*100 -> 3.9965941
A10: Cordillera Administrative Region | B10: =i_C8!C11 -> 556690.66 | C10: 554273.85 | D10: =(C10/$B10)*100 -> 99.565861 | E10: 2580.5649 | F10: =(E10/$B10)*100 -> 0.46355455 | G10: 1277366 | H10: 1226462 | I10: =(H10/$G10)*100 -> 96.014924 | J10: 57996 | K10: =(J10/$G10)*100 -> 4.5402805
A11: Region I - Ilocos Region | B11: =i_C8!C12 -> 2001306 | C11: 1966006.2 | D11: =(C11/$B11)*100 -> 98.236162 | E11: 39298.321 | F11: =(E11/$B11)*100 -> 1.9636338 | G11: 3683268 | H11: 3518329 | I11: =(H11/$G11)*100 -> 95.521939 | J11: 168734 | K11: =(J11/$G11)*100 -> 4.5810948
A12: Region II - Cagayan Valley | B12: =i_C8!C13 -> 1344522.4 | C12: 1334417.1 | D12: =(C12/$B12)*100 -> 99.248404 | E12: 18682.305 | F12: =(E12/$B12)*100 -> 1.3895123 | G12: 2451050 | H12: 2440210 | I12: =(H12/$G12)*100 -> 99.557741 | J12: 15419 | K12: =(J12/$G12)*100 -> 0.62907733
A13: Region III - Central Luzon | B13: =i_C8!C14 -> 4847012.4 | C13: 4765111.8 | D13: =(C13/$B13)*100 -> 98.310287 | E13: 88332.684 | F13: =(E13/$B13)*100 -> 1.8224151 | G13: 9021916 | H13: 8721921 | I13: =(H13/$G13)*100 -> 96.674819 | J13: 330842 | K13: =(J13/$G13)*100 -> 3.6670924
A14: Region IV-A - CALABARZON | B14: =i_C8!C15 -> 5566196.9 | C14: 5405404.8 | D14: =(C14/$B14)*100 -> 97.111276 | E14: 173992.38 | F14: =(E14/$B14)*100 -> 3.1258754 | G14: 12081369 | H14: 11816558 | I14: =(H14/$G14)*100 -> 97.808104 | J14: 326586 | K14: =(J14/$G14)*100 -> 2.7032201
A15: MIMAROPA Region | B15: =i_C8!C16 -> 761294.45 | C15: 756606.72 | D15: =(C15/$B15)*100 -> 99.384243 | E15: 7634.8877 | F15: =(E15/$B15)*100 -> 1.0028824 | G15: 1900349 | H15: 1884654 | I15: =(H15/$G15)*100 -> 99.174099 | J15: 29388 | K15: =(J15/$G15)*100 -> 1.5464528
A16: Region V - Bicol Region | B16: =i_C8!C17 -> 1690938.7 | C16: 1665837.5 | D16: =(C16/$B16)*100 -> 98.515541 | E16: 17517.414 | F16: =(E16/$B16)*100 -> 1.0359579 | G16: 3577241 | H16: 3486357 | I16: =(H16/$G16)*100 -> 97.459383 | J16: 95944 | K16: =(J16/$G16)*100 -> 2.682067
A17: Region VI - Western Visayas | B17: =i_C8!C18 -> 2159752 | C17: 2130834.4 | D17: =(C17/$B17)*100 -> 98.661067 | E17: 42559.781 | F17: =(E17/$B17)*100 -> 1.9705865 | G17: 4990093 | H17: 4828205 | I17: =(H17/$G17)*100 -> 96.755812 | J17: 178398 | K17: =(J17/$G17)*100 -> 3.5750436
A18: Region VII - Central Visayas | B18: =i_C8!C19 -> 1476407.2 | C18: 1454815.6 | D18: =(C18/$B18)*100 -> 98.537557 | E18: 21946.062 | F18: =(E18/$B18)*100 -> 1.4864505 | G18: 5296648 | H18: 5121217 | I18: =(H18/$G18)*100 -> 96.687886 | J18: 213237 | K18: =(J18/$G18)*100 -> 4.0258858
A19: Region VIII - Eastern Visayas | B19: =i_C8!C20 -> 1318328.5 | C19: 1287336 | D19: =(C19/$B19)*100 -> 97.649108 | E19: 36231.534 | F19: =(E19/$B19)*100 -> 2.7482933 | G19: 2705948 | H19: 2679128 | I19: =(H19/$G19)*100 -> 99.00885 | J19: 43261 | K19: =(J19/$G19)*100 -> 1.5987373
... A25: Bangsamoro Autonomous Region in Muslim Mindanao | B25: =i_C8!C26 -> 779688.76 | C25: 774492.55 | D25: =(C25/$B25)*100 -> 99.333553 | E25: 2695.8593 | F25: =(E25/$B25)*100 -> 0.34576095 | G25: 2608489 | H25: 2540113 | I25: =(H25/$G25)*100 -> 97.378712 | J25: 74592 | K25: =(J25/$G25)*100 -> 2.8595865
A28: Notes:
A29: Details may not add up to totals due to rounding.
A30: p Estimates are preliminary and may change
A31: r Revised
A32: Source of data: Philippine Statistics Authority, 2024 National Information and Communications Technology Household Survey.

Sheet i_C12
A1: BACK TO LIST
A2: Table #. Number and Proportion of Individuals With ICT Device and Active SIM by Details Used in SIM Card Registration and Region, Philippines: 2024p
A4: Region | B4: With ICT Device and Active SIM | C4: Details Used in SIM Registration
C5: Owner | E5: Relative | G5: Others*
C6: Number | D6: Proportion | E6: Number | F6: Proportion | G6: Number | H6: Proportion
A8: PHILIPPINES | B8: 72989986 | C8: 61831391 | D8: =(C8/$B8)*100 -> 84.712156 | E8: 9212540 | F8: =(E8/$B8)*100 -> 12.621649 | G8: 2195966 | H8: =(G8/$B8)*100 -> 3.0085853
A9: National Capital Region | B9: 10953079 | C9: 9823627 | D9: =(C9/$B9)*100 -> 89.688269 | E9: 990700 | F9: =(E9/$B9)*100 -> 9.0449453 | G9: 166319 | H9: =(G9/$B9)*100 -> 1.518468
A10: Cordillera Administrative Region | B10: 1278264 | C10: 965232 | D10: =(C10/$B10)*100 -> 75.511162 | E10: 266527 | F10: =(E10/$B10)*100 -> 20.850701 | G10: 48335 | H10: =(G10/$B10)*100 -> 3.7813003
A11: Region I - Ilocos Region | B11: 3690995 | C11: 3080402 | D11: =(C11/$B11)*100 -> 83.457225 | E11: 570484 | F11: =(E11/$B11)*100 -> 15.456103 | G11: 40109 | H11: =(G11/$B11)*100 -> 1.0866718
A12: Region II - Cagayan Valley | B12: 2454608 | C12: 2126558 | D12: =(C12/$B12)*100 -> 86.635341 | E12: 269894 | F12: =(E12/$B12)*100 -> 10.995401 | G12: 65047 | H12: =(G12/$B12)*100 -> 2.6499954
A13: Region III - Central Luzon | B13: 9031169 | C13: 7850092 | D13: =(C13/$B13)*100 -> 86.922213 | E13: 1137264 | F13: =(E13/$B13)*100 -> 12.592655 | G13: 53207 | H13: =(G13/$B13)*100 -> 0.58914854
A14: Region IV-A - CALABARZON | B14: 12098018 | C14: 10136640 | D14: =(C14/$B14)*100 -> 83.787609 | E14: 1737288 | F14: =(E14/$B14)*100 -> 14.360104 | G14: 271609 | H14: =(G14/$B14)*100 -> 2.2450702
A15: MIMAROPA Region | B15: 1905284 | C15: 1418050 | D15: =(C15/$B15)*100 -> 74.427224 | E15: 395749 | F15: =(E15/$B15)*100 -> 20.771129 | G15: 103019 | H15: =(G15/$B15)*100 -> 5.4070154
A16: Region V - Bicol Region | B16: 3580110 | C16: 2765560 | D16: =(C16/$B16)*100 -> 77.247906 | E16: 604525 | F16: =(E16/$B16)*100 -> 16.885654 | G16: 222533 | H16: =(G16/$B16)*100 -> 6.2158146
A17: Region VI - Western Visayas | B17: 4997303 | C17: 4421971 | D17: =(C17/$B17)*100 -> 88.48715 | E17: 481861 | F17: =(E17/$B17)*100 -> 9.6424211 | G17: 134427 | H17: =(G17/$B17)*100 -> 2.689991
A18: Region VII - Central Visayas | B18: 5303296 | C18: 4464670 | D18: =(C18/$B18)*100 -> 84.186702 | E18: 614620 | F18: =(E18/$B18)*100 -> 11.589396 | G18: 236453 | H18: =(G18/$B18)*100 -> 4.4586046
A19: Region VIII - Eastern Visayas | B19: 2707991 | C19: 2318040 | D19: =(C19/$B19)*100 -> 85.599989 | E19: 271039 | F19: =(E19/$B19)*100 -> 10.008859 | G19: 130022 | H19: =(G19/$B19)*100 -> 4.8014192
... A25: Bangsamoro Autonomous Region in Muslim Mindanao | B25: 2609448 | C25: 2050292 | D25: =(C25/$B25)*100 -> 78.571867 | E25: 366282 | F25: =(E25/$B25)*100 -> 14.036762 | G25: 220473 | H25: =(G25/$B25)*100 -> 8.4490283
A28: Notes:
A29: Details may not add up to totals due to rounding.
A30: * Includes Friend, Pre-Registered, Employer, Others
A31: p Estimates are preliminary and may change
A32: Source of data: Philippine Statistics Authority, 2024 National Information and Communications Technology Household Survey.

Sheet i_C13
A1: BACK TO LIST
A2: Table #. Number and Proportion of Individuals with ICT Device and Active SIM Who Did Not Use Own Information in SIM Registration by Main Reason and Region, Philippines: 2024p
A4: Region | B4: Did Not Use Own Information | C4: Main Reason for Not Using Own Information
C5: No Government Issued ID | E5: Don't Know the Process | G5: Child (Parental Control) | I5: Others
C6: Number | D6: Proportion | E6: Number | F6: Proportion | G6: Number | H6: Proportion | I6: Number | J6: Proportion
A8: PHILIPPINES | B8: 11364259 | C8: 2216397 | D8: =(C8/$B8)*100 -> 19.503225 | E8: 4214914 | F8: =(E8/$B8)*100 -> 37.089211 | G8: 4221711 | H8: =(G8/$B8)*100 -> 37.149021 | I8: 641634 | J8: =(I8/$B8)*100 -> 5.6460698
A9: National Capital Region | B9: 1157019 | C9: 170718 | D9: =(C9/$B9)*100 -> 14.754987 | E9: 171704 | F9: =(E9/$B9)*100 -> 14.840206 | G9: 735644 | H9: =(G9/$B9)*100 -> 63.580978 | I9: 76015 | J9: =(I9/$B9)*100 -> 6.5699008
A10: Cordillera Administrative Region | B10: 313801 | C10: 51946 | D10: =(C10/$B10)*100 -> 16.553803 | E10: 172795 | F10: =(E10/$B10)*100 -> 55.065153 | G10: 80371 | H10: =(G10/$B10)*100 -> 25.612092 | I10: 8238 | J10: =(I10/$B10)*100 -> 2.6252306
A11: Region I - Ilocos Region | B11: 610593 | C11: 164712 | D11: =(C11/$B11)*100 -> 26.975743 | E11: 339389 | F11: =(E11/$B11)*100 -> 55.583507 | G11: 99020 | H11: =(G11/$B11)*100 -> 16.217022 | I11: 7472 | J11: =(I11/$B11)*100 -> 1.2237284
A12: Region II - Cagayan Valley | B12: 334942 | C12: 44891 | D12: =(C12/$B12)*100 -> 13.402619 | E12: 96425 | F12: =(E12/$B12)*100 -> 28.788566 | G12: 155869 | H12: =(G12/$B12)*100 -> 46.536117 | I12: 36205 | J12: =(I12/$B12)*100 -> 10.809334
A13: Region III - Central Luzon | B13: 1190471 | C13: 207672 | D13: =(C13/$B13)*100 -> 17.444524 | E13: 206739 | F13: =(E13/$B13)*100 -> 17.366152 | G13: 666321 | H13: =(G13/$B13)*100 -> 55.971208 | I13: 103731 | J13: =(I13/$B13)*100 -> 8.713442
A14: Region IV-A - CALABARZON | B14: 1999010 | C14: 407989 | D14: =(C14/$B14)*100 -> 20.409553 | E14: 561307 | F14: =(E14/$B14)*100 -> 28.079249 | G14: 890818 | H14: =(G14/$B14)*100 -> 44.562959 | I14: 123577 | J14: =(I14/$B14)*100 -> 6.18191
A15: MIMAROPA Region | B15: 498094 | C15: 157666 | D15: =(C15/$B15)*100 -> 31.653865 | E15: 234774 | F15: =(E15/$B15)*100 -> 47.134477 | G15: 91597 | H15: =(G15/$B15)*100 -> 18.389501 | I15: 11194 | J15: =(I15/$B15)*100 -> 2.247367
A16: Region V - Bicol Region | B16: 827059 | C16: 179570 | D16: =(C16/$B16)*100 -> 21.711873 | E16: 312753 | F16: =(E16/$B16)*100 -> 37.815077 | G16: 291568 | H16: =(G16/$B16)*100 -> 35.253591 | I16: 37089 | J16: =(I16/$B16)*100 -> 4.4844443
A17: Region VI - Western Visayas | B17: 610574 | C17: 85860 | D17: =(C17/$B17)*100 -> 14.062178 | E17: 239694 | F17: =(E17/$B17)*100 -> 39.257158 | G17: 250844 | H17: =(G17/$B17)*100 -> 41.083308 | I17: 24194 | J17: =(I17/$B17)*100 -> 3.9625009
A18: Region VII - Central Visayas | B18: 845861 | C18: 91989 | D18: =(C18/$B18)*100 -> 10.875191 | E18: 324772 | F18: =(E18/$B18)*100 -> 38.395434 | G18: 352369 | H18: =(G18/$B18)*100 -> 41.658027 | I18: 72168 | J18: =(I18/$B18)*100 -> 8.5318983
A19: Region VIII - Eastern Visayas | B19: 399041 | C19: 82391 | D19: =(C19/$B19)*100 -> 20.647252 | E19: 178025 | F19: =(E19/$B19)*100 -> 44.61321 | G19: 96974 | H19: =(G19/$B19)*100 -> 24.301763 | I19: 37257 | J19: =(I19/$B19)*100 -> 9.3366346
... A25: Bangsamoro Autonomous Region in Muslim Mindanao | B25: 576944 | C25: 78025 | D25: =(C25/$B25)*100 -> 13.523843 | E25: 423573 | F25: =(E25/$B25)*100 -> 73.416657 | G25: 74825 | H25: =(G25/$B25)*100 -> 12.969196 | I25: 959 | J25: =(I25/$B25)*100 -> 0.16622064
A28: Notes:
A29: Details may not add up to totals due to rounding.
A30: p Estimates are preliminary and may change
A31: Source of data: Philippine Statistics Authority, 2024 National Information and Communications Technology Household Survey.

Sheet i_C14
A1: BACK TO LIST
A2: Table #. Number and Proportion of Individuals with ICT Device, Active SIM and Registered SIM by Main Difficulty Encountered and Region, Philippines: 2024p
A4: Region | B4: With ICT Device and Active SIM | C4: Main Difficulty Encountered in SIM Registration
C5: Difficulty in Accessing the Registration Site | E5: Difficulty in Uploading ID | G5: Difficulty in Accomplishing the Registration Form | I5: Registration Site Took a Long Time to Load | K5: Did not Encounter any Difficulty | M5: Others
C6: Number | D6: Proportion | E6: Number | F6: Proportion | G6: Number | H6: Proportion | I6: Number | J6: Proportion | K6: Number | L6: Proportion | M6: Number | N6: Proportion
A8: PHILIPPINES | B8: 72989986 | C8: 4883635 | D8: =(C8/$B8)*100 -> 6.6908288 | E8: 8332250 | F8: =(E8/$B8)*100 -> 11.415607 | G8: 2134333 | H8: =(G8/$B8)*100 -> 2.924145 | I8: 3083032 | J8: =(I8/$B8)*100 -> 4.2239109 | K8: 54540047 | L8: =(K8/$B8)*100 -> 74.722643 | M8: 665541 | N8: =(M8/$B8)*100 -> 0.91182508
A9: National Capital Region | B9: 10953079 | C9: 652608 | D9: =(C9/$B9)*100 -> 5.958215 | E9: 868748 | F9: =(E9/$B9)*100 -> 7.9315414 | G9: 210371 | H9: =(G9/$B9)*100 -> 1.9206563 | I9: 352841 | J9: =(I9/$B9)*100 -> 3.2213864 | K9: 8881891 | L9: =(K9/$B9)*100 -> 81.090358 | M9: 80039 | N9: =(M9/$B9)*100 -> 0.7307443
A10: Cordillera Administrative Region | B10: 1278264 | C10: 103654 | D10: =(C10/$B10)*100 -> 8.1089665 | E10: 332694 | F10: =(E10/$B10)*100 -> 26.027018 | G10: 51103 | H10: =(G10/$B10)*100 -> 3.997844 | I10: 88462 | J10: =(I10/$B10)*100 -> 6.9204797 | K10: 738591 | L10: =(K10/$B10)*100 -> 57.780787 | M10: 8493 | N10: =(M10/$B10)*100 -> 0.66441674
A11: Region I - Ilocos Region | B11: 3690995 | C11: 166998 | D11: =(C11/$B11)*100 -> 4.524471 | E11: 761215 | F11: =(E11/$B11)*100 -> 20.623572 | G11: 163060 | H11: =(G11/$B11)*100 -> 4.4177789 | I11: 268703 | J11: =(I11/$B11)*100 -> 7.2799611 | K11: 2333201 | L11: =(K11/$B11)*100 -> 63.213334 | M11: 3622 | N11: =(M11/$B11)*100 -> 0.098130721
A12: Region II - Cagayan Valley | B12: 2454608 | C12: 79050 | D12: =(C12/$B12)*100 -> 3.2204735 | E12: 375411 | F12: =(E12/$B12)*100 -> 15.294133 | G12: 71533 | H12: =(G12/$B12)*100 -> 2.9142331 | I12: 226673 | J12: =(I12/$B12)*100 -> 9.2345906 | K12: 1682607 | L12: =(K12/$B12)*100 -> 68.548909 | M12: 28850 | N12: =(M12/$B12)*100 -> 1.1753404
A13: Region III - Central Luzon | B13: 9031169 | C13: 244177 | D13: =(C13/$B13)*100 -> 2.7037142 | E13: 1130607 | F13: =(E13/$B13)*100 -> 12.518944 | G13: 339327 | H13: =(G13/$B13)*100 -> 3.7572877 | I13: 251348 | J13: =(I13/$B13)*100 -> 2.783117 | K13: 7076712 | L13: =(K13/$B13)*100 -> 78.35876 | M13: 26853 | N13: =(M13/$B13)*100 -> 0.29733692
A14: Region IV-A - CALABARZON | B14: 12098018 | C14: 1014060 | D14: =(C14/$B14)*100 -> 8.3820341 | E14: 943927 | F14: =(E14/$B14)*100 -> 7.8023276 | G14: 241450 | H14: =(G14/$B14)*100 -> 1.9957815 | I14: 278432 | J14: =(I14/$B14)*100 -> 2.3014679 | K14: 9519762 | L14: =(K14/$B14)*100 -> 78.688608 | M14: 199953 | N14: =(M14/$B14)*100 -> 1.6527749
A15: MIMAROPA Region | B15: 1905284 | C15: 132075 | D15: =(C15/$B15)*100 -> 6.9320374 | E15: 352871 | F15: =(E15/$B15)*100 -> 18.520651 | G15: 77609 | H15: =(G15/$B15)*100 -> 4.073356 | I15: 93165 | J15: =(I15/$B15)*100 -> 4.8898222 | K15: 1230557 | L15: =(K15/$B15)*100 -> 64.586539 | M15: 44592 | N15: =(M15/$B15)*100 -> 2.3404385
A16: Region V - Bicol Region | B16: 3580110 | C16: 148774 | D16: =(C16/$B16)*100 -> 4.1555706 | E16: 531567 | F16: =(E16/$B16)*100 -> 14.847784 | G16: 66701 | H16: =(G16/$B16)*100 -> 1.8630992 | I16: 130357 | J16: =(I16/$B16)*100 -> 3.6411451 | K16: 2709645 | L16: =(K16/$B16)*100 -> 75.686082 | M16: 42149 | N16: =(M16/$B16)*100 -> 1.1773102
A17: Region VI - Western Visayas | B17: 4997303 | C17: 331894 | D17: =(C17/$B17)*100 -> 6.6414624 | E17: 606803 | F17: =(E17/$B17)*100 -> 12.14261 | G17: 115088 | H17: =(G17/$B17)*100 -> 2.3030022 | I17: 178732 | J17: =(I17/$B17)*100 -> 3.5765692 | K17: 3780626 | L17: =(K17/$B17)*100 -> 75.653327 | M17: 13654 | N17: =(M17/$B17)*100 -> 0.27322738
A18: Region VII - Central Visayas | B18: 5303296 | C18: 232552 | D18: =(C18/$B18)*100 -> 4.3850466 | E18: 349238 | F18: =(E18/$B18)*100 -> 6.5853009 | G18: 139987 | H18: =(G18/$B18)*100 -> 2.6396226 | I18: 331055 | J18: =(I18/$B18)*100 -> 6.2424387 | K18: 4270866 | L18: =(K18/$B18)*100 -> 80.532295 | M18: 31165 | N18: =(M18/$B18)*100 -> 0.58765341
A19: Region VIII - Eastern Visayas | B19: 2707991 | C19: 225430 | D19: =(C19/$B19)*100 -> 8.3246215 | E19: 301428 | F19: =(E19/$B19)*100 -> 11.131056 | G19: 40970 | H19: =(G19/$B19)*100 -> 1.5129297 | I19: 85526 | J19: =(I19/$B19)*100 -> 3.1582823 | K19: 2043178 | L19: =(K19/$B19)*100 -> 75.449955 | M19: 27647 | N19: =(M19/$B19)*100 -> 1.0209414
... A25: Bangsamoro Autonomous Region in Muslim Mindanao | B25: 2609448 | C25: 645288 | D25: =(C25/$B25)*100 -> 24.728908 | E25: 523269 | F25: =(E25/$B25)*100 -> 20.052862 | G25: 217706 | H25: =(G25/$B25)*100 -> 8.3429905 | I25: 212311 | J25: =(I25/$B25)*100 -> 8.1362418 | K25: 1117753 | L25: =(K25/$B25)*100 -> 42.834845 | M25: 8486 | N25: =(M25/$B25)*100 -> 0.32520288
A28: Notes:
A29: Details may not add up to totals due to rounding.
A30: p Estimates are preliminary and may change
A31: Source of data: Philippine Statistics Authority, 2024 National Information and Communications Technology Household Survey.

Sheet i_C15
A1: BACK TO LIST
A2: Table #. Individual Average Monthly Spending on Load or Subscription by Region, Philippines: 2019 and 2024p
A4: Region | B4: Average Monthly Spending
B5: 2019 | C5: 2024
A7: PHILIPPINES | B7: 255.5118 | C7: 265.3
A8: National Capital Region | B8: 338.68679 | C8: 320.3
A9: Cordillera Administrative Region | B9: 252.93832 | C9: 281.5
A10: Region I - Ilocos Region | B10: 186.50589 | C10: 284.5
A11: Region II - Cagayan Valley | B11: 218.05583 | C11: 271.5
A12: Region III - Central Luzon | B12: 289.09803 | C12: 289.4
A13: Region IV-A - CALABARZON | B13: 287.43904 | C13: 240.4
A14: MIMAROPA Region | B14: 223.18947 | C14: 301.9
A15: Region V - Bicol Region | B15: 185.38549 | C15: 236.6
A16: Region VI - Western Visayas | B16: 311.07504 | C16: 260.1
A17: Region VII - Central Visayas | B17: 195.33539 | C17: 288.8
A18: Region VIII - Eastern Visayas | B18: 219.41155 | C18: 261.7
... A24: Bangsamoro Autonomous Region in Muslim Mindanao | B24: 126.95219 | C24: 252.7
A27: Notes:
A28: p Estimates are preliminary and may change
A29: Source of data: Philippine Statistics Authority, 2024 National Information and Communications Technology Household Survey.

Sheet c29
A1: BACK TO LIST
A2: Table #. Number and Proportion of Households with Communal or Shared Computer That Can be Used by Any Household Member at Any Time by Region, Philippines: 2019 and 2024p
A4: Region | B4: 2019 | E4: 2024
B5: Total Households | C5: With Communal or Shared Computer | E5: Total Households | F5: With Communal or Shared Computer
C6: Number | D6: Proportion | F6: Number | G6: Proportion
A8: PHILIPPINES | B8: ='Estimated Totals'!B7 -> 23360960 | C8: 5557498 | D8: =(C8/B8)*100 -> 23.789682 | E8: 27793884 | F8: 3006985 | G8: =(F8/E8)*100 -> 10.818873
A9: National Capital Region | B9: ='Estimated Totals'!B8 -> 3009545 | C9: 1117522 | D9: =(C9/B9)*100 -> 37.13259 | E9: 3667731 | F9: 667137 | G9: =(F9/E9)*100 -> 18.189366
A10: Cordillera Administrative Region | B10: ='Estimated Totals'!B9 -> 388188 | C10: 116362 | D10: =(C10/B10)*100 -> 29.975682 | E10: 468413 | F10: 62352 | G10: =(F10/E10)*100 -> 13.31133
A11: Region I - Ilocos Region | B11: ='Estimated Totals'!B10 -> 1250337 | C11: 291371 | D11: =(C11/B11)*100 -> 23.303397 | E11: 1316881 | F11: 119488 | G11: =(F11/E11)*100 -> 9.0735609
A12: Region II - Cagayan Valley | B12: ='Estimated Totals'!B11 -> 855893 | C12: 146921 | D12: =(C12/B12)*100 -> 17.165814 | E12: 934252 | F12: 97834 | G12: =(F12/E12)*100 -> 10.471907
A13: Region III - Central Luzon | B13: ='Estimated Totals'!B12 -> 2823200 | C13: 654747 | D13: =(C13/B13)*100 -> 23.191662 | E13: 3161851 | F13: 390356 | G13: =(F13/E13)*100 -> 12.345806
A14: Region IV-A - CALABARZON | B14: ='Estimated Totals'!B13 -> 3486186 | C14: 1488913 | D14: =(C14/B14)*100 -> 42.708937 | E14: 4369198 | F14: 580410 | G14: =(F14/E14)*100 -> 13.284131
A15: MIMAROPA Region | B15: ='Estimated Totals'!B14 -> 686916 | C15: 99090 | D15: =(C15/B15)*100 -> 14.425345 | E15: 828498 | F15: 63200 | G15: =(F15/E15)*100 -> 7.6282622
A16: Region V - Bicol Region | B16: ='Estimated Totals'!B15 -> 1030986 | C16: 162411 | D16: =(C16/B16)*100 -> 15.752978 | E16: 1384033 | F16: 137805 | G16: =(F16/E16)*100 -> 9.9567713
A17: Region VI - Western Visayas | B17: ='Estimated Totals'!B16 -> 1705556 | C17: 281295 | D17: =(C17/B17)*100 -> 16.492862 | E17: 2040922 | F17: 129132 | G17: =(F17/E17)*100 -> 6.3271404
A18: Region VII - Central Visayas | B18: ='Estimated Totals'!B17 -> 1820052 | C18: 297076 | D18: =(C18/B18)*100 -> 16.322391 | E18: 2077216 | F18: 189142 | G18: =(F18/E18)*100 -> 9.1055528
A19: Region VIII - Eastern Visayas | B19: ='Estimated Totals'!B18 -> 1042723 | C19: 148345 | D19: =(C19/B19)*100 -> 14.226693 | E19: 1200913 | F19: 71688 | G19: =(F19/E19)*100 -> 5.9694582
... A25: Bangsamoro Autonomous Region in Muslim Mindanao | B25: ='Estimated Totals'!B24 -> 521349 | C25: 44261 | D25: =(C25/B25)*100 -> 8.4897065 | E25: 846042 | F25: 38074 | G25: =(F25/E25)*100 -> 4.5002494
A28: Notes:
A29: Details may not add up to totals due to rounding.
A30: p Estimates are preliminary and may change
A31: Source of data: Philippine Statistics Authority, 2024 National Information and Communications Technology Household Survey.

Sheet c30_a to d
A1: BACK TO LIST
A2: Table #. Number and Proportion of Households with Communal or Shared Computer That Can be Used by Any Household Member at Any Time by Type and Region, Philippines: 2019r and 2024p
A4: Region | B4: 2019 | K4: 2024
B5: With Communal or Shared Computer | C5: Type of Computer | K5: With Communal or Shared Computer | L5: Type of Computer
C6: Desktop | E6: Laptop | G6: Tablet or Similar Device | I6: Others | L6: Desktop | N6: Laptop | P6: Tablet or Similar Device | R6: Others
C7: Number | D7: Proportion | E7: Number | F7: Proportion | G7: Number | H7: Proportion | I7: Number | J7: Proportion | L7: Number | M7: Proportion | N7: Number | O7: Proportion | P7: Number | Q7: Proportion | R7: Number | S7: Proportion
A9: PHILIPPINES | B9: 5557498 | C9: 1373230 | D9: =(C9/$B9)*100 -> 24.709501 | E9: 3661577 | F9: =(E9/$B9)*100 -> 65.88535 | G9: 2191905 | H9: =(G9/$B9)*100 -> 39.4405 | I9: 17195 | J9: =IFERROR((I9/$B9)*100,"-") -> 0.30940182 | K9: 3006985 | L9: 916719 | M9: =(L9/$K9)*100 -> 30.486318 | N9: 2363672 | O9: =(N9/$K9)*100 -> 78.606046 | P9: 681463 | Q9: =(P9/$K9)*100 -> 22.662667 | R9: 4599 | S9: =(R9/$K9)*100 -> 0.1529439
A10: National Capital Region | B10: 1117522 | C10: 411311 | D10: =(C10/$B10)*100 -> 36.805629 | E10: 801970 | F10: =(E10/$B10)*100 -> 71.76324 | G10: 323043 | H10: =(G10/$B10)*100 -> 28.907082 | I10: 1436 | J10: =IFERROR((I10/$B10)*100,"-") -> 0.12849859 | K10: 667137 | L10: 216586 | M10: =(L10/$K10)*100 -> 32.464996 | N10: 516556 | O10: =(N10/$K10)*100 -> 77.428774 | P10: 166450 | Q10: =(P10/$K10)*100 -> 24.949898 | R10: 67 | S10: =(R10/$K10)*100 -> 0.010042915
A11: Cordillera Administrative Region | B11: 116362 | C11: 29433 | D11: =(C11/$B11)*100 -> 25.29434 | E11: 86727 | F11: =(E11/$B11)*100 -> 74.532064 | G11: 26372 | H11: =(G11/$B11)*100 -> 22.663756 | I11: - | J11: =IFERROR((I11/$B11)*100,"-") -> - | K11: 62352 | L11: 17940 | M11: =(L11/$K11)*100 -> 28.772132 | N11: 49654 | O11: =(N11/$K11)*100 -> 79.634976 | P11: 10728 | Q11: =(P11/$K11)*100 -> 17.205543 | R11: 383 | S11: =(R11/$K11)*100 -> 0.61425455
A12: Region I - Ilocos Region | B12: 291371 | C12: 42040 | D12: =(C12/$B12)*100 -> 14.42834 | E12: 214846 | F12: =(E12/$B12)*100 -> 73.736233 | G12: 146709 | H12: =(G12/$B12)*100 -> 50.35127 | I12: 1115 | J12: =IFERROR((I12/$B12)*100,"-") -> 0.38267364 | K12: 119488 | L12: 32644 | M12: =(L12/$K12)*100 -> 27.319898 | N12: 95336 | O12: =(N12/$K12)*100 -> 79.787092 | P12: 32691 | Q12: =(P12/$K12)*100 -> 27.359233 | R12: 0 | S12: =(R12/$K12)*100 -> 0
A13: Region II - Cagayan Valley | B13: 146921 | C13: 25267 | D13: =(C13/$B13)*100 -> 17.197678 | E13: 113696 | F13: =(E13/$B13)*100 -> 77.385806 | G13: 27309 | H13: =(G13/$B13)*100 -> 18.58754 | I13: 1345 | J13: =IFERROR((I13/$B13)*100,"-") -> 0.91545797 | K13: 97834 | L13: 12578 | M13: =(L13/$K13)*100 -> 12.856471 | N13: 83606 | O13: =(N13/$K13)*100 -> 85.456999 | P13: 18056 | Q13: =(P13/$K13)*100 -> 18.455752 | R13: 0 | S13: =(R13/$K13)*100 -> 0
A14: Region III - Central Luzon | B14: 654747 | C14: 165868 | D14: =(C14/$B14)*100 -> 25.333144 | E14: 444351 | F14: =(E14/$B14)*100 -> 67.866061 | G14: 214727 | H14: =(G14/$B14)*100 -> 32.795416 | I14: - | J14: =IFERROR((I14/$B14)*100,"-") -> - | K14: 390356 | L14: 113732 | M14: =(L14/$K14)*100 -> 29.135456 | N14: 302263 | O14: =(N14/$K14)*100 -> 77.432651 | P14: 104432 | Q14: =(P14/$K14)*100 -> 26.753015 | R14: 1180 | S14: =(R14/$K14)*100 -> 0.30228817
A15: Region IV-A - CALABARZON | B15: 1488913 | C15: 315901 | D15: =(C15/$B15)*100 -> 21.216888 | E15: 745307 | F15: =(E15/$B15)*100 -> 50.057122 | G15: 847654 | H15: =(G15/$B15)*100 -> 56.931063 | I15: 324 | J15: =IFERROR((I15/$B15)*100,"-") -> 0.021760842 | K15: 580410 | L15: 207594 | M15: =(L15/$K15)*100 -> 35.766786 | N15: 433890 | O15: =(N15/$K15)*100 -> 74.755776 | P15: 144672 | Q15: =(P15/$K15)*100 -> 24.925828 | R15: 0 | S15: =(R15/$K15)*100 -> 0
A16: MIMAROPA Region | B16: 99090 | C16: 10111 | D16: =(C16/$B16)*100 -> 10.203855 | E16: 75268 | F16: =(E16/$B16)*100 -> 75.959229 | G16: 32627 | H16: =(G16/$B16)*100 -> 32.926632 | I16: 658 | J16: =IFERROR((I16/$B16)*100,"-") -> 0.66404279 | K16: 63200 | L16: 12484 | M16: =(L16/$K16)*100 -> 19.753165 | N16: 51680 | O16: =(N16/$K16)*100 -> 81.772152 | P16: 13552 | Q16: =(P16/$K16)*100 -> 21.443038 | R16: 297 | S16: =(R16/$K16)*100 -> 0.46993671
A17: Region V - Bicol Region | B17: 162411 | C17: 30424 | D17: =(C17/$B17)*100 -> 18.732721 | E17: 123591 | F17: =(E17/$B17)*100 -> 76.097678 | G17: 59931 | H17: =(G17/$B17)*100 -> 36.900826 | I17: 651 | J17: =IFERROR((I17/$B17)*100,"-") -> 0.40083492 | K17: 137805 | L17: 35824 | M17: =(L17/$K17)*100 -> 25.996154 | N17: 116821 | O17: =(N17/$K17)*100 -> 84.772686 | P17: 19355 | Q17: =(P17/$K17)*100 -> 14.045209 | R17: 548 | S17: =(R17/$K17)*100 -> 0.39766336
A18: Region VI - Western Visayas | B18: 281295 | C18: 66499 | D18: =(C18/$B18)*100 -> 23.640306 | E18: 187237 | F18: =(E18/$B18)*100 -> 66.562506 | G18: 116412 | H18: =(G18/$B18)*100 -> 41.384312 | I18: 399 | J18: =IFERROR((I18/$B18)*100,"-") -> 0.14184397 | K18: 129132 | L18: 33714 | M18: =(L18/$K18)*100 -> 26.108168 | N18: 112965 | O18: =(N18/$K18)*100 -> 87.480253 | P18: 20230 | Q18: =(P18/$K18)*100 -> 15.66614 | R18: 0 | S18: =(R18/$K18)*100 -> 0
A19: Region VII - Central Visayas | B19: 297076 | C19: 80646 | D19: =(C19/$B19)*100 -> 27.146589 | E19: 206775 | F19: =(E19/$B19)*100 -> 69.603401 | G19: 89778 | H19: =(G19/$B19)*100 -> 30.22055 | I19: 2588 | J19: =IFERROR((I19/$B19)*100,"-") -> 0.87115755 | K19: 189142 | L19: 71753 | M19: =(L19/$K19)*100 -> 37.936048 | N19: 149167 | O19: =(N19/$K19)*100 -> 78.865085 | P19: 44572 | Q19: =(P19/$K19)*100 -> 23.565364 | R19: 800 | S19: =(R19/$K19)*100 -> 0.42296264
A20: Region VIII - Eastern Visayas | B20: 148345 | C20: 24630 | D20: =(C20/$B20)*100 -> 16.603189 | E20: 112648 | F20: =(E20/$B20)*100 -> 75.936499 | G20: 47455 | H20: =(G20/$B20)*100 -> 31.989619 | I20: 958 | J20: =IFERROR((I20/$B20)*100,"-") -> 0.6457919 | K20: 71688 | L20: 13746 | M20: =(L20/$K20)*100 -> 19.174757 | N20: 60478 | O20: =(N20/$K20)*100 -> 84.362794 | P20: 15057 | Q20: =(P20/$K20)*100 -> 21.003515 | R20: 829 | S20: =(R20/$K20)*100 -> 1.1564
A21: Region IX - Zamboanga Peninsula | B21: 84974 | C21: 18459 | D21: =(C21/$B21)*100 -> 21.723115 | E21: 67399 | F21: =(E21/$B21)*100 -> 79.317203 | G21: 33108 | H21: =(G21/$B21)*100 -> 38.962506 | I21: 376 | J21: =IFERROR((I21/$B21)*100,"-") -> 0.44248829 | K21: 46837 | L21: 10407 | M21: =(L21/$K21)*100 -> 22.219613 | N21: 37665 | O21: =(N21/$K21)*100 -> 80.417192 | P21: 11452 | Q21: =(P21/$K21)*100 -> 24.450755 | R21: 0 | S21: =(R21/$K21)*100 -> 0
A22: Region X - Northern Mindanao | B22: 152576 | C22: 39845 | D22: =(C22/$B22)*100 -> 26.114854 | E22: 108913 | F22: =(E22/$B22)*100 -> 71.382786 | G22: 59259 | H22: =(G22/$B22)*100 -> 38.839005 | I22: - | J22: =IFERROR((I22/$B22)*100,"-") -> - | K22: 146395 | L22: 54281 | M22: =(L22/$K22)*100 -> 37.078452 | N22: 110136 | O22: =(N22/$K22)*100 -> 75.232078 | P22: 24656 | Q22: =(P22/$K22)*100 -> 16.842105 | R22: 495 | S22: =(R22/$K22)*100 -> 0.3381263
A23: Region XI - Davao Region | B23: 212526 | C23: 48679 | D23: =(C23/$B23)*100 -> 22.904962 | E23: 160423 | F23: =(E23/$B23)*100 -> 75.483941 | G23: 68103 | H23: =(G23/$B23)*100 -> 32.04455 | I23: 1719 | J23: =IFERROR((I23/$B23)*100,"-") -> 0.80884221 | K23: 100970 | L23: 26277 | M23: =(L23/$K23)*100 -> 26.024562 | N23: 76627 | O23: =(N23/$K23)*100 -> 75.890859 | P23: 18988 | Q23: =(P23/$K23)*100 -> 18.805586 | R23: 0 | S23: =(R23/$K23)*100 -> 0
A24: Region XII - SOCCSKSARGEN | B24: 162894 | C24: 39987 | D24: =(C24/$B24)*100 -> 24.547865 | E24: 118068 | F24: =(E24/$B24)*100 -> 72.481491 | G24: 42669 | H24: =(G24/$B24)*100 -> 26.194335 | I24: 5157 | J24: =IFERROR((I24/$B24)*100,"-") -> 3.1658625 | K24: 125471 | L24: 40141 | M24: =(L24/$K24)*100 -> 31.992253 | N24: 101281 | O24: =(N24/$K24)*100 -> 80.720645 | P24: 19329 | Q24: =(P24/$K24)*100 -> 15.405153 | R24: 0 | S24: =(R24/$K24)*100 -> 0
A25: Region XIII - Caraga | B25: 96216 | C25: 18854 | D25: =(C25/$B25)*100 -> 19.595493 | E25: 64238 | F25: =(E25/$B25)*100 -> 66.764364 | G25: 42814 | H25: =(G25/$B25)*100 -> 44.497797 | I25: 469 | J25: =IFERROR((I25/$B25)*100,"-") -> 0.48744492 | K25: 40695 | L25: 10902 | M25: =(L25/$K25)*100 -> 26.789532 | N25: 30807 | O25: =(N25/$K25)*100 -> 75.702175 | P25: 11523 | Q25: =(P25/$K25)*100 -> 28.315518 | R25: 0 | S25: =(R25/$K25)*100 -> 0
A26: Bangsamoro Autonomous Region in Muslim Mindanao | B26: 44261 | C26: 5276 | D26: =(C26/$B26)*100 -> 11.920201 | E26: 30120 | F26: =(E26/$B26)*100 -> 68.05088 | G26: 13934 | H26: =(G26/$B26)*100 -> 31.48144 | I26: - | J26: =IFERROR((I26/$B26)*100,"-") -> - | K26: 38074 | L26: 6115 | M26: =(L26/$K26)*100 -> 16.060829 | N26: 34741 | O26: =(N26/$K26)*100 -> 91.245995 | P26: 5720 | Q26: =(P26/$K26)*100 -> 15.023376 | R26: 0 | S26: =(R26/$K26)*100 -> 0
A29: Notes:
A30: Details may not add up to totals due to rounding.
A31: p Estimates are preliminary and may change
A32: r Revised
A33: Source of data: Philippine Statistics Authority, 2024 National Information and Communications Technology Household Survey.

Sheet c29_C31_a to C31_g
A1: BACK TO LIST
A2: Table #. Number and Proportion of Households Accessing a Computer by Alternative Access Method and Region, Philippines: 2019 and 2024p
A4: Region | B4: 2019 | M4: 2024
B5: Total Households | C5: Alternative Access Method | M5: Total Households | N5: Alternative Access Method
C6: School/Work | E6: Relatives/ Friends/Neighbors | G6: Barangay/ Community Computers | I6: Computer Shops | K6: Others | N6: School | P6: Work | R6: Relatives/ Friends/Neighbors | T6: Barangay/ Community Computers | V6: Computer Shops | X6: Pisonet | Z6: Others
C7: Number | D7: Proportion | E7: Number | F7: Proportion | G7: Number | H7: Proportion | I7: Number | J7: Proportion | K7: Number | L7: Proportion | N7: Number | O7: Proportion | P7: Number | Q7: Proportion | R7: Number | S7: Proportion | T7: Number | U7: Proportion | V7: Number | W7: Proportion | X7: Number | Y7: Proportion | Z7: Number | AA7: Proportion
A9: PHILIPPINES | B9: ='Estimated Totals'!B7 -> 23360960 | C9: 3672255 | D9: =(C9/$B9)*100 -> 15.719624 | E9: 1406742 | F9: =(E9/$B9)*100 -> 6.0217645 | G9: 273362 | H9: =(G9/$B9)*100 -> 1.170166 | I9: 8137749 | J9: =(I9/$B9)*100 -> 34.834823 | K9: 609873 | L9: =(K9/$B9)*100 -> 2.6106504 | M9: 27793884 | N9: 5259073 | O9: =(N9/$M9)*100 -> 18.921692 | P9: 5477573 | Q9: =(P9/$M9)*100 -> 19.707836 | R9: 4419694 | S9: =(R9/$M9)*100 -> 15.901678 | T9: 858483 | U9: =(T9/$M9)*100 -> 3.0887479 | V9: 4853300 | W9: =(V9/$M9)*100 -> 17.461755 | X9: 4012681 | Y9: =(X9/$M9)*100 -> 14.437281 | Z9: 181993 | AA9: =(Z9/$M9)*100 -> 0.65479513
A10: National Capital Region | B10: ='Estimated Totals'!B8 -> 3009545 | C10: 529212 | D10: =(C10/$B10)*100 -> 17.584452 | E10: 183393 | F10: =(E10/$B10)*100 -> 6.0937118 | G10: 11333 | H10: =(G10/$B10)*100 -> 0.37656855 | I10: 1202151 | J10: =(I10/$B10)*100 -> 39.94461 | K10: 72812 | L10: =(K10/$B10)*100 -> 2.419369 | M10: 3667731 | N10: 539224 | O10: =(N10/$M10)*100 -> 14.701842 | P10: 1251863 | Q10: =(P10/$M10)*100 -> 34.131811 | R10: 617584 | S10: =(R10/$M10)*100 -> 16.838312 | T10: 51408 | U10: =(T10/$M10)*100 -> 1.4016295 | V10: 662537 | W10: =(V10/$M10)*100 -> 18.063947 | X10: 387450 | Y10: =(X10/$M10)*100 -> 10.563752 | Z10: 1044 | AA10: =(Z10/$M10)*100 -> 0.028464465
A11: Cordillera Administrative Region | B11: ='Estimated Totals'!B9 -> 388188 | C11: 77139 | D11: =(C11/$B11)*100 -> 19.871557 | E11: 6215 | F11: =(E11/$B11)*100 -> 1.6010284 | G11: 18806 | H11: =(G11/$B11)*100 -> 4.8445599 | I11: 106880 | J11: =(I11/$B11)*100 -> 27.533051 | K11: 6592 | L11: =(K11/$B11)*100 -> 1.6981463 | M11: 468413 | N11: 114311 | O11: =(N11/$M11)*100 -> 24.403891 | P11: 85212 | Q11: =(P11/$M11)*100 -> 18.191639 | R11: 130465 | S11: =(R11/$M11)*100 -> 27.852557 | T11: 44615 | U11: =(T11/$M11)*100 -> 9.5247143 | V11: 94151 | W11: =(V11/$M11)*100 -> 20.099997 | X11: 26319 | Y11: =(X11/$M11)*100 -> 5.6187595 | Z11: 359 | AA11: =(Z11/$M11)*100 -> 0.076641767
A12: Region I - Ilocos Region | B12: ='Estimated Totals'!B10 -> 1250337 | C12: 131179 | D12: =(C12/$B12)*100 -> 10.491491 | E12: 100036 | F12: =(E12/$B12)*100 -> 8.000723 | G12: 2212 | H12: =(G12/$B12)*100 -> 0.1769123 | I12: 454726 | J12: =(I12/$B12)*100 -> 36.368275 | K12: 55347 | L12: =(K12/$B12)*100 -> 4.4265666 | M12: 1316881 | N12: 365440 | O12: =(N12/$M12)*100 -> 27.750419 | P12: 274078 | Q12: =(P12/$M12)*100 -> 20.812663 | R12: 351369 | S12: =(R12/$M12)*100 -> 26.68191 | T12: 126549 | U12: =(T12/$M12)*100 -> 9.6097521 | V12: 426762 | W12: =(V12/$M12)*100 -> 32.407028 | X12: 53196 | Y12: =(X12/$M12)*100 -> 4.039545 | Z12: 0 | AA12: =(Z12/$M12)*100 -> 0
A13: Region II - Cagayan Valley | B13: ='Estimated Totals'!B11 -> 855893 | C13: 83914 | D13: =(C13/$B13)*100 -> 9.8042629 | E13: 39942 | F13: =(E13/$B13)*100 -> 4.6667048 | G13: 35092 | H13: =(G13/$B13)*100 -> 4.1000452 | I13: 392258 | J13: =(I13/$B13)*100 -> 45.830261 | K13: 15761 | L13: =(K13/$B13)*100 -> 1.8414685 | M13: 934252 | N13: 241421 | O13: =(N13/$M13)*100 -> 25.841101 | P13: 155188 | Q13: =(P13/$M13)*100 -> 16.610936 | R13: 155267 | S13: =(R13/$M13)*100 -> 16.619392 | T13: 29258 | U13: =(T13/$M13)*100 -> 3.1317032 | V13: 164899 | W13: =(V13/$M13)*100 -> 17.650377 | X13: 28020 | Y13: =(X13/$M13)*100 -> 2.9991908 | Z13: 11367 | AA13: =(Z13/$M13)*100 -> 1.2166953
A14: Region III - Central Luzon | B14: ='Estimated Totals'!B12 -> 2823200 | C14: 270128 | D14: =(C14/$B14)*100 -> 9.5681496 | E14: 195663 | F14: =(E14/$B14)*100 -> 6.9305398 | G14: 31114 | H14: =(G14/$B14)*100 -> 1.1020827 | I14: 877237 | J14: =(I14/$B14)*100 -> 31.072436 | K14: 6160 | L14: =(K14/$B14)*100 -> 0.21819212 | M14: 3161851 | N14: 543172 | O14: =(N14/$M14)*100 -> 17.178925 | P14: 546460 | Q14: =(P14/$M14)*100 -> 17.282914 | R14: 545151 | S14: =(R14/$M14)*100 -> 17.241515 | T14: 74043 | U14: =(T14/$M14)*100 -> 2.3417612 | V14: 459584 | W14: =(V14/$M14)*100 -> 14.535283 | X14: 163743 | Y14: =(X14/$M14)*100 -> 5.178707 | Z14: 26133 | AA14: =(Z14/$M14)*100 -> 0.82650954
A15: Region IV-A - CALABARZON | B15: ='Estimated Totals'!B13 -> 3486186 | C15: 714557 | D15: =(C15/$B15)*100 -> 20.496812 | E15: 266782 | F15: =(E15/$B15)*100 -> 7.6525464 | G15: 2205 | H15: =(G15/$B15)*100 -> 0.063249637 | I15: 1646400 | J15: =(I15/$B15)*100 -> 47.226396 | K15: 94218 | L15: =(K15/$B15)*100 -> 2.7026097 | M15: 4369198 | N15: 828096 | O15: =(N15/$M15)*100 -> 18.953044 | P15: 1011162 | Q15: =(P15/$M15)*100 -> 23.142966 | R15: 827369 | S15: =(R15/$M15)*100 -> 18.936404 | T15: 111048 | U15: =(T15/$M15)*100 -> 2.5416106 | V15: 747237 | W15: =(V15/$M15)*100 -> 17.102384 | X15: 506128 | Y15: =(X15/$M15)*100 -> 11.584002 | Z15: 1850 | AA15: =(Z15/$M15)*100 -> 0.042341867
A16: MIMAROPA Region | B16: ='Estimated Totals'!B14 -> 686916 | C16: 229378 | D16: =(C16/$B16)*100 -> 33.392438 | E16: 26982 | F16: =(E16/$B16)*100 -> 3.9279912 | G16: 5658 | H16: =(G16/$B16)*100 -> 0.8236815 | I16: 164601 | J16: =(I16/$B16)*100 -> 23.962319 | K16: 33633 | L16: =(K16/$B16)*100 -> 4.8962319 | M16: 828498 | N16: 191872 | O16: =(N16/$M16)*100 -> 23.159018 | P16: 148661 | Q16: =(P16/$M16)*100 -> 17.943435 | R16: 122809 | S16: =(R16/$M16)*100 -> 14.823089 | T16: 31253 | U16: =(T16/$M16)*100 -> 3.7722481 | V16: 163396 | W16: =(V16/$M16)*100 -> 19.721955 | X16: 90439 | Y16: =(X16/$M16)*100 -> 10.916019 | Z16: 3513 | AA16: =(Z16/$M16)*100 -> 0.42402034
A17: Region V - Bicol Region | B17: ='Estimated Totals'!B15 -> 1030986 | C17: 111995 | D17: =(C17/$B17)*100 -> 10.862902 | E17: 18074 | F17: =(E17/$B17)*100 -> 1.7530791 | G17: 5013 | H17: =(G17/$B17)*100 -> 0.48623357 | I17: 180200 | J17: =(I17/$B17)*100 -> 17.478414 | K17: 164826 | L17: =(K17/$B17)*100 -> 15.98722 | M17: 1384033 | N17: 256214 | O17: =(N17/$M17)*100 -> 18.512131 | P17: 193053 | Q17: =(P17/$M17)*100 -> 13.948584 | R17: 130125 | S17: =(R17/$M17)*100 -> 9.4018712 | T17: 28223 | U17: =(T17/$M17)*100 -> 2.0391855 | V17: 214876 | W17: =(V17/$M17)*100 -> 15.525352 | X17: 167724 | Y17: =(X17/$M17)*100 -> 12.118497 | Z17: 13755 | AA17: =(Z17/$M17)*100 -> 0.99383468
A18: Region VI - Western Visayas | B18: ='Estimated Totals'!B16 -> 1705556 | C18: 315566 | D18: =(C18/$B18)*100 -> 18.502236 | E18: 211556 | F18: =(E18/$B18)*100 -> 12.403932 | G18: 15906 | H18: =(G18/$B18)*100 -> 0.93259911 | I18: 483299 | J18: =(I18/$B18)*100 -> 28.336742 | K18: 11322 | L18: =(K18/$B18)*100 -> 0.66383045 | M18: 2040922 | N18: 417834 | O18: =(N18/$M18)*100 -> 20.472806 | P18: 334031 | Q18: =(P18/$M18)*100 -> 16.366672 | R18: 292385 | S18: =(R18/$M18)*100 -> 14.326123 | T18: 104849 | U18: =(T18/$M18)*100 -> 5.137335 | V18: 392816 | W18: =(V18/$M18)*100 -> 19.246987 | X18: 341235 | Y18: =(X18/$M18)*100 -> 16.719649 | Z18: 28008 | AA18: =(Z18/$M18)*100 -> 1.3723209
